Workbook

Sheet Resumen
A1: Tracker de visibilidad Shiftia — resumen
A2: Todos los contadores se calculan solos desde las demás pestañas. Solo se rellenan a mano las filas de 'Marca (GSC)' y las notas del mes.
A4: Directorios (bloque 1)
A5: Publicados | B5: =COUNTIF(Directorios!$C$3:$C$27,"Publicado") | C5: Objetivo: los 10 precargados en 4-6 semanas.
A6: En curso | B6: =COUNTIF(Directorios!$C$3:$C$27,"En curso")
A7: Pendientes | B7: =COUNTIF(Directorios!$C$3:$C$27,"Pendiente")
A9: Reseñas (paso 1.4)
A10: Publicadas (reseña o testimonio) | B10: =COUNTIF(Reseñas!$F$3:$F$22,"Publicada")+COUNTIF(Reseñas!$F$3:$F$22,"Testimonio") | C10: Objetivo del plan: 3-5 en 2 semanas.
A11: Enviadas / en recordatorio | B11: =COUNTIF(Reseñas!$F$3:$F$22,"Enviado")+COUNTIF(Reseñas!$F$3:$F$22,"Recordatorio")
A12: Pendientes de enviar | B12: =COUNTIF(Reseñas!$F$3:$F$22,"Pendiente")
A13: Declinaron / sin respuesta | B13: =COUNTIF(Reseñas!$F$3:$F$22,"Declinó")+COUNTIF(Reseñas!$F$3:$F$22,"Sin respuesta")
A15: Prensa y listados (paso 2.1 y sección 4.1)
A16: Publicados | B16: =COUNTIF(Prensa!$G$3:$G$24,"Publicado")
A17: Respondidos (en conversación) | B17: =COUNTIF(Prensa!$G$3:$G$24,"Respondido")
A18: Enviados / en seguimiento | B18: =COUNTIF(Prensa!$G$3:$G$24,"Enviado")+COUNTIF(Prensa!$G$3:$G$24,"Seguimiento")
A19: Pendientes de enviar | B19: =COUNTIF(Prensa!$G$3:$G$24,"Pendiente")
A20: Declinados / sin respuesta | B20: =COUNTIF(Prensa!$G$3:$G$24,"Declinado")+COUNTIF(Prensa!$G$3:$G$24,"Sin respuesta")
A22: LinkedIn (paso 2.2)
A23: Posts publicados en perfil | B23: =COUNTIF(LinkedIn!$E$3:$E$38,"Sí") | C23: 1 post/semana. Las 12 semanas del calendario están precargadas.
A24: Posts publicados en página | B24: =COUNTIF(LinkedIn!$F$3:$F$38,"Sí")
A25: Posts planificados sin publicar | B25: =COUNTIF(LinkedIn!$E$3:$E$38,"No")
A26: Impresiones acumuladas | B26: =SUM(LinkedIn!$G$3:$G$38)
A27: Media de impresiones por post publicado | B27: =IF(COUNTIF(LinkedIn!$E$3:$E$38,"Sí")=0,"",SUMIF(LinkedIn!$E$3:$E$38,"Sí",LinkedIn!$G$3:$G$38)/COUNTIF(LinkedIn!$E$3:$E$38,"Sí"))
A29: GEO mensual (paso 4.2) — mes indicado en B:
A30: Mes a resumir (AAAA-MM) | B30: 2026-09 | C30: Cambia este valor para ver otro mes.
A31: Respuestas registradas (puntuadas) | B31: =COUNTIFS('GEO mensual'!$A$3:$A$178,$B$30,'GEO mensual'!$K$3:$K$178,"<>") | C31: 44 = 11 consultas × 4 motores.
A32: Veces que aparece Shiftia | B32: =COUNTIFS('GEO mensual'!$A$3:$A$178,$B$30,'GEO mensual'!$E$3:$E$178,"Sí")
A33: % de apariciones | B33: =IF(B31=0,"",B32/B31)
A34: Puntuación media 0-10 | B34: =IF(COUNTIFS('GEO mensual'!$A$3:$A$178,$B$30,'GEO mensual'!$K$3:$K$178,"<>")=0,"",AVERAGEIFS('GEO mensual'!$K$3:$K$178,'GEO mensual'!$A$3:$A$178,$B$30)) | C34: 0-1 invisibles · 2-4 aparece en algunas · 5-7 objetivo 6 meses · 8-10 objetivo 12 meses.
A35: Media ChatGPT | B35: =IF(COUNTIFS('GEO mensual'!$A$3:$A$178,$B$30,'GEO mensual'!$D$3:$D$178,"ChatGPT (búsqueda web)",'GEO mensual'!$K$3:$K$178,"<>")=0,"",AVERAGEIFS('GEO mensual'!$K$3:$K$178,'GEO mensual'!$A$3:$A$178,$B$30,'GEO mensual'!$D$3:$D$178,"ChatGPT (búsqueda web)"))
A36: Media Claude | B36: =IF(COUNTIFS('GEO mensual'!$A$3:$A$178,$B$30,'GEO mensual'!$D$3:$D$178,"Claude",'GEO mensual'!$K$3:$K$178,"<>")=0,"",AVERAGEIFS('GEO mensual'!$K$3:$K$178,'GEO mensual'!$A$3:$A$178,$B$30,'GEO mensual'!$D$3:$D$178,"Claude"))
A37: Media Perplexity | B37: =IF(COUNTIFS('GEO mensual'!$A$3:$A$178,$B$30,'GEO mensual'!$D$3:$D$178,"Perplexity",'GEO mensual'!$K$3:$K$178,"<>")=0,"",AVERAGEIFS('GEO mensual'!$K$3:$K$178,'GEO mensual'!$A$3:$A$178,$B$30,'GEO mensual'!$D$3:$D$178,"Perplexity"))
A38: Media Gemini | B38: =IF(COUNTIFS('GEO mensual'!$A$3:$A$178,$B$30,'GEO mensual'!$D$3:$D$178,"Gemini",'GEO mensual'!$K$3:$K$178,"<>")=0,"",AVERAGEIFS('GEO mensual'!$K$3:$K$178,'GEO mensual'!$A$3:$A$178,$B$30,'GEO mensual'!$D$3:$D$178,"Gemini"))
A39: Respuestas con precio incorrecto | B39: =COUNTIFS('GEO mensual'!$A$3:$A$178,$B$30,'GEO mensual'!$I$3:$I$178,"No") | C39: Cada una es una fuente que corregir (sección 3.5 del kit).
A40: Respuestas con descripción incorrecta | B40: =COUNTIFS('GEO mensual'!$A$3:$A$178,$B$30,'GEO mensual'!$J$3:$J$178,"No") | C40: Vigilar sobre todo si nos llaman ETT o bolsa de personal.
A42: GSC quick wins (paso 4.1)
A43: Quick wins detectados (pos. 4-15, ≥ 20 impr.) | B43: =COUNTIF('GSC quick wins'!$M$3:$M$45,"Quick win")
A44: Títulos rotos (CTR < 2 % en pos. 1-5) | B44: =COUNTIF('GSC quick wins'!$M$3:$M$45,"Título roto")
A45: Acciones pendientes | B45: =COUNTIF('GSC quick wins'!$G$3:$G$45,"Pendiente")+COUNTIF('GSC quick wins'!$G$3:$G$45,"Reescribir título/meta")+COUNTIF('GSC quick wins'!$G$3:$G$45,"Optimizar H1 + primer párrafo")+COUNTIF('GSC quick wins'!$G$3:$G$45,"Enlazar internamente")
A46: Acciones hechas | B46: =COUNTIF('GSC quick wins'!$G$3:$G$45,"Hecho")
...

Sheet Directorios
A1: Bloque 1 del plan (pasos 1.1-1.3 y 2.3). Estado: Pendiente / En curso / Publicado. Fecha = día en que se cambia el estado. Añade filas para cualquier directorio que citen los motores de IA (pestaña GEO mensual).
A2: Plataforma | B2: URL de alta | C2: Estado | D2: Fecha | E2: URL de la ficha | F2: Notas
A3: SoftDoit | B3: https://www.softwaredoit.es/registra-solucion-de-software/index.html | C3: Pendiente | F3: Ficha básica gratuita. Categorías: Software de gestión de turnos y Software para residencias. Descripción del paso 1.1 del plan.
A4: Capterra | B4: https://www.capterra.com/vendors/sign-up | C4: Pendiente | F4: Un solo alta de Gartner Digital Markets cubre Capterra, GetApp y Software Advice. Categoría: Employee Scheduling / Nurse Scheduling. Logo + 3-5 capturas + descripción en español e inglés.
A5: GetApp | B5: https://www.capterra.com/vendors/sign-up | C5: Pendiente | F5: Se crea automáticamente con el alta de Capterra. Comprobar que la ficha aparece y guardar su URL.
A6: Software Advice | B6: https://www.capterra.com/vendors/sign-up | C6: Pendiente | F6: Se crea automáticamente con el alta de Capterra. Comprobar que la ficha aparece y guardar su URL.
A7: Google Business Profile | B7: https://business.google.com | C7: Pendiente | F7: Perfil 'Shiftia' en Oviedo, categoría Empresa de software. Web, teléfono, horario, logo y 2-3 fotos. Da el enlace corto de reseñas.
A8: Crunchbase | B8: https://www.crunchbase.com/add-new | C8: Pendiente | F8: Perfil de empresa: Shiftia (Highkey Labs Software Solutions), Oviedo, fundador Diego Ciborro. Fuente de entidades para los LLM. [COMPROBAR URL DE ALTA]
A9: Product Hunt | B9: https://www.producthunt.com/posts/new | C9: Pendiente | F9: Opcional. Lanzamiento con vídeo de 30 s de ShiftiaCore. Elegir martes o miércoles. [COMPROBAR URL DE ALTA]
A10: G2 | B10: https://www.g2.com | C10: Pendiente | F10: Reclamar/crear perfil de producto en G2 (sección para vendedores). Categoría Employee Scheduling. [COMPROBAR URL DE ALTA]
A11: Comparasoftware | B11: https://www.comparasoftware.com | C11: Pendiente | F11: Directorio en español (España y Latinoamérica). Buscar 'Registrar software' en su web. [COMPROBAR URL DE ALTA]
A12: AppVizer | B12: https://www.appvizer.es | C12: Pendiente | F12: Directorio europeo con edición en español. Buscar 'Añadir mi software' en su web. [COMPROBAR URL DE ALTA]

Sheet Reseñas
A1: Paso 1.4 del plan. Objetivo: 3-5 reseñas en 2 semanas. Los mensajes por cliente están en resenas-mensajes.md. 'Recordatorio' se calcula solo (Enviado + 5 días) si dejas la celda con la fórmula.
A2: Cliente | B2: Contacto | C2: Canal | D2: Enviado | E2: Recordatorio (día 5-7) | F2: Estado | G2: Plataforma | H2: Enlace reseña / testimonio | I2: Notas
A3: SPAR Supermercados (Gran Canaria, retail) | B3: [NOMBRE Y CARGO] | C3: WhatsApp | E3: =IF(D3="","",D3+5) | F3: Pendiente | G3: Google | H3: [ENLACE RESEÑA PUBLICADA] | I3: Prioridad 1 (marca reconocible). Mensaje en resenas-mensajes.md, 2.1.
A4: Servicios sanitarios en Asturias (cliente confidencial) | B4: [NOMBRE Y CARGO] | C4: Email | E4: =IF(D4="","",D4+7) | F4: Pendiente | G4: Capterra | I4: Prioridad 1. Sin nombre público: reseña solo con sector. Mensaje en 2.4. Recordatorio a los 7 días, solo email.
A5: NONWATIO (Valencia, frío industrial) | B5: [NOMBRE Y CARGO] | C5: WhatsApp | E5: =IF(D5="","",D5+5) | F5: Pendiente | G5: Google | I5: Prioridad 1. Mensaje en 2.2.
A6: La Otra Abacería (León, hostelería) | B6: [NOMBRE Y CARGO] | C6: WhatsApp | E6: =IF(D6="","",D6+5) | F6: Pendiente | G6: Google | I6: Misma semana, sin agobiar. Mensaje en 2.3.
A7: Servicio de Urología, H. U. Clínico San Cecilio (Granada) | B7: [NOMBRE Y CARGO] | C7: Email | E7: =IF(D7="","",D7+7) | F7: Pendiente | G7: Google | I7: Sanidad pública: puede que prefieran testimonio o carta interna en vez de reseña pública. Mensaje en 2.5. Recordatorio a los 7 días, solo email; sin WhatsApp.
E8: =IF(D8="","",D8+5)
E9: =IF(D9="","",D9+5)
E10: =IF(D10="","",D10+5)
E11: =IF(D11="","",D11+5)
E12: =IF(D12="","",D12+5)
E13: =IF(D13="","",D13+5)
E14: =IF(D14="","",D14+5)
E15: =IF(D15="","",D15+5)
E16: =IF(D16="","",D16+5)
E17: =IF(D17="","",D17+5)
E18: =IF(D18="","",D18+5)
E19: =IF(D19="","",D19+5)
... E22: =IF(D22="","",D22+5)

Sheet Prensa
A1: Paso 2.1 del plan (pitch en plan.md). También sirve para los listados/comparativas a los que se pide inclusión (sección 4.1 del kit GSC+GEO): sección = 'Listado/comparativa'. 'Seguimiento' se calcula solo (Fecha envío + 7).
A2: Medio | B2: Sección | C2: Contacto / email | D2: Periodista | E2: Fecha envío | F2: Seguimiento (+7 días) | G2: Respuesta / estado | H2: Publicado (URL) | I2: Notas
A3: La Nueva España | B3: Oviedo / Economía | C3: [EMAIL REDACCIÓN O FORMULARIO] | D3: [PERIODISTA] | F3: =IF(E3="","",E3+7) | G3: Pendiente | I3: Ángulo: empresa de Oviedo, tecnología hecha en Asturias.
A4: El Comercio | B4: Gijón | C4: [EMAIL REDACCIÓN O FORMULARIO] | D4: [PERIODISTA] | F4: =IF(E4="","",E4+7) | G4: Pendiente | I4: Ángulo: enfermero del Hospital de Jove (Gijón) que crea una IA para los cuadrantes.
A5: Asturias Semanal | B5: Economía / empresas | C5: [EMAIL REDACCIÓN O FORMULARIO] | D5: [PERIODISTA] | F5: =IF(E5="","",E5+7) | G5: Pendiente | I5: Ángulo: startup asturiana que compite con software nacional e internacional.
A6: [MEDIO DE STARTUPS / ECONOMÍA ASTURIANA] | B6: Startups | C6: [EMAIL REDACCIÓN O FORMULARIO] | D6: [PERIODISTA] | F6: =IF(E6="","",E6+7) | G6: Pendiente | I6: El plan deja abierto el medio concreto; elegir uno de emprendimiento asturiano.
A7: Geriatricarea | B7: Residencias / tecnología | C7: [EMAIL REDACCIÓN O FORMULARIO] | D7: [PERIODISTA] | F7: =IF(E7="","",E7+7) | G7: Pendiente | I7: Ángulo residencias: cobertura 24/7, equidad de noches, convenio configurable. Sin inventar clientes de residencias.
A8: Balance Sociosanitario | B8: Sociosanitario | C8: [EMAIL REDACCIÓN O FORMULARIO] | D8: [PERIODISTA] | F8: =IF(E8="","",E8+7) | G8: Pendiente | I8: Ángulo residencias / sociosanitario.
A9: iSanidad | B9: Sanidad / innovación | C9: [EMAIL REDACCIÓN O FORMULARIO] | D9: [PERIODISTA] | F9: =IF(E9="","",E9+7) | G9: Pendiente | I9: Ángulo sanitario: Servicio de Urología del H. U. Clínico San Cecilio (Granada) planifica con Shiftia.
F10: =IF(E10="","",E10+7)
F11: =IF(E11="","",E11+7)
F12: =IF(E12="","",E12+7)
F13: =IF(E13="","",E13+7)
F14: =IF(E14="","",E14+7)
F15: =IF(E15="","",E15+7)
F16: =IF(E16="","",E16+7)
F17: =IF(E17="","",E17+7)
F18: =IF(E18="","",E18+7)
F19: =IF(E19="","",E19+7)
F20: =IF(E20="","",E20+7)
F21: =IF(E21="","",E21+7)
... F24: =IF(E24="","",E24+7)

Sheet LinkedIn
A1: Paso 2.2 del plan. Calendario y textos completos en linkedin-calendario-y-posts.md. Métricas: se apuntan a los 7 días de publicar (Analíticas del post). 'Interacción %' = (reacciones + comentarios + clics) / impresiones.
A2: Semana | B2: Fecha | C2: Tipo | D2: Tema | E2: Publicado en perfil | F2: Publicado en página | G2: Impresiones | H2: Reacciones | I2: Comentarios | J2: Clics | K2: Interacción %
A3: 1 | B3: 46273 | C3: Personal | D3: De hacer cuadrantes a mano en el hospital a fundar Shiftia | E3: No | F3: No | K3: =IF(OR(G3="",G3=0),"",(H3+I3+J3)/G3)
A4: 2 | B4: 46280 | C4: Normativa | D4: Descanso mínimo de 12 h entre turnos (art. 34.3 ET) | E4: No | F4: No | K4: =IF(OR(G4="",G4=0),"",(H4+I4+J4)/G4)
A5: 3 | B5: 46288 | C5: Producto | D5: Vídeo de 30 s: ShiftiaCore genera un cuadrante mensual desde cero | E5: No | F5: No | K5: =IF(OR(G5="",G5=0),"",(H5+I5+J5)/G5)
A6: 4 | B6: 46294 | C6: Caso | D6: Servicio de Urología del H. U. Clínico San Cecilio (Granada) | E6: No | F6: No | K6: =IF(OR(G6="",G6=0),"",(H6+I6+J6)/G6)
A7: 5 | B7: 46301 | C7: Personal | D7: La equidad de noches es un problema de salud y de justicia | E7: No | F7: No | K7: =IF(OR(G7="",G7=0),"",(H7+I7+J7)/G7)
A8: 6 | B8: 46309 | C8: Normativa | D8: Registro horario (art. 34.9 ET) y por qué el cuadrante no es el registro | E8: No | F8: No | K8: =IF(OR(G8="",G8=0),"",(H8+I8+J8)/G8)
A9: 7 | B9: 46315 | C9: Producto | D9: Gestor de Cobertura IA: una baja a las 7:00, 3 candidatos en menos de 1 s | E9: No | F9: No | K9: =IF(OR(G9="",G9=0),"",(H9+I9+J9)/G9)
A10: 8 | B10: 46322 | C10: Caso | D10: Hostelería: La Otra Abacería (León), turno partido y fines de semana | E10: No | F10: No | K10: =IF(OR(G10="",G10=0),"",(H10+I10+J10)/G10)
A11: 9 | B11: 46329 | C11: Personal | D11: Por qué publicamos comparativas honestas | E11: No | F11: No | K11: =IF(OR(G11="",G11=0),"",(H11+I11+J11)/G11)
A12: 10 | B12: 46336 | C12: Normativa | D12: Turnos rotativos y convenio 2026 | E12: No | F12: No | K12: =IF(OR(G12="",G12=0),"",(H12+I12+J12)/G12)
A13: 11 | B13: 46343 | C13: Producto | D13: Lector PDF con IA + auditoría gratuita de cuadrante | E13: No | F13: No | K13: =IF(OR(G13="",G13=0),"",(H13+I13+J13)/G13)
A14: 12 | B14: 46350 | C14: Caso | D14: Retail: SPAR Supermercados (Gran Canaria) | E14: No | F14: No | K14: =IF(OR(G14="",G14=0),"",(H14+I14+J14)/G14)
K15: =IF(OR(G15="",G15=0),"",(H15+I15+J15)/G15)
K16: =IF(OR(G16="",G16=0),"",(H16+I16+J16)/G16)
K17: =IF(OR(G17="",G17=0),"",(H17+I17+J17)/G17)
K18: =IF(OR(G18="",G18=0),"",(H18+I18+J18)/G18)
K19: =IF(OR(G19="",G19=0),"",(H19+I19+J19)/G19)
K20: =IF(OR(G20="",G20=0),"",(H20+I20+J20)/G20)
K21: =IF(OR(G21="",G21=0),"",(H21+I21+J21)/G21)
K22: =IF(OR(G22="",G22=0),"",(H22+I22+J22)/G22)
K23: =IF(OR(G23="",G23=0),"",(H23+I23+J23)/G23)
K24: =IF(OR(G24="",G24=0),"",(H24+I24+J24)/G24)
K25: =IF(OR(G25="",G25=0),"",(H25+I25+J25)/G25)
K26: =IF(OR(G26="",G26=0),"",(H26+I26+J26)/G26)
... K38: =IF(OR(G38="",G38=0),"",(H38+I38+J38)/G38)

Sheet GEO mensual
A1: Paso 4.2 del plan. Primer lunes laborable de cada mes, 11 consultas × 4 motores. Rúbrica 0-10: aparece 3 · posición (1.ª 3 / 2.ª-3.ª 2 / 4.ª+ 1) · descripción correcta 2 (parcial 1) · precio correcto o sin precio falso 1 · cita fuente de terceros 1. Si no aparece: 0. Para el mes siguiente copia las 44 filas y cambia el mes.
A2: Mes (AAAA-MM) | B2: Nº | C2: Consulta | D2: Motor | E2: Aparece | F2: Posición | G2: Herramientas citadas | H2: Fuentes citadas (URL) | I2: Precio correcto | J2: Descripción correcta | K2: Puntuación 0-10 | L2: Notas
A3: 2026-09 | B3: 1 | C3: mejor software de turnos para residencias en España | D3: ChatGPT (búsqueda web)
A4: 2026-09 | B4: 1 | C4: mejor software de turnos para residencias en España | D4: Claude
A5: 2026-09 | B5: 1 | C5: mejor software de turnos para residencias en España | D5: Perplexity
A6: 2026-09 | B6: 1 | C6: mejor software de turnos para residencias en España | D6: Gemini
A7: 2026-09 | B7: 2 | C7: alternativas a aTurnos | D7: ChatGPT (búsqueda web)
A8: 2026-09 | B8: 2 | C8: alternativas a aTurnos | D8: Claude
A9: 2026-09 | B9: 2 | C9: alternativas a aTurnos | D9: Perplexity
A10: 2026-09 | B10: 2 | C10: alternativas a aTurnos | D10: Gemini
A11: 2026-09 | B11: 3 | C11: software cuadrantes enfermería | D11: ChatGPT (búsqueda web)
A12: 2026-09 | B12: 3 | C12: software cuadrantes enfermería | D12: Claude
A13: 2026-09 | B13: 3 | C13: software cuadrantes enfermería | D13: Perplexity
A14: 2026-09 | B14: 3 | C14: software cuadrantes enfermería | D14: Gemini
... A46: 2026-09 | B46: 11 | C46: Shiftia opiniones | D46: Gemini

Sheet GSC quick wins
A1: Paso 4.1 del plan. Quick win = posición 4-15 con ≥ 20 impresiones (3 meses). Título roto = CTR < 2 % en posición 1-5. CTR, Δ posición, Tipo y longitudes se calculan solos. Long. título objetivo 50-60; meta 140-155.
A2: Consulta | B2: Página | C2: Impresiones | D2: Clics | E2: CTR | F2: Posición | G2: Acción | H2: Título nuevo | I2: Meta nueva | J2: Fecha cambio | K2: Posición +30 días | L2: Δ posición | M2: Tipo | N2: Long. título | O2: Long. meta | P2: Notas
A3: [consulta de GSC] | B3: https://www.shiftia.es/ | E3: =IF(OR(C3="",C3=0),"",D3/C3) | G3: Pendiente | H3: Software de turnos con IA desde 29 €/mes | Shiftia | I3: Genera el cuadrante mensual en segundos respetando el convenio y reparte las noches con equidad. Desde 29 €/mes, sin permanencia. Demo sin registro. | L3: =IF(OR(F3="",K3=""),"",F3-K3) | M3: =IF(OR(C3="",F3=""),"",IF(AND(F3>=4,F3<=15,C3>=20),"Quick win",IF(AND(F3<=5,E3<0.02),"Título roto","Revisar"))) | N3: =IF(H3="","",LEN(H3)) | O3: =IF(I3="","",LEN(I3))
A4: [consulta de GSC] | B4: https://www.shiftia.es/recursos/descanso-minimo-entre-turnos | E4: =IF(OR(C4="",C4=0),"",D4/C4) | G4: Pendiente | H4: Descanso mínimo entre turnos 2026: ley y calculadora gratis | I4: Cuántas horas de descanso hay entre turnos según el Estatuto de los Trabajadores, el Estatuto Marco y tu convenio. Calculadora gratis y ejemplos reales. | L4: =IF(OR(F4="",K4=""),"",F4-K4) | M4: =IF(OR(C4="",F4=""),"",IF(AND(F4>=4,F4<=15,C4>=20),"Quick win",IF(AND(F4<=5,E4<0.02),"Título roto","Revisar"))) | N4: =IF(H4="","",LEN(H4)) | O4: =IF(I4="","",LEN(I4))
A5: [consulta de GSC] | B5: https://www.shiftia.es/recursos/excel-vs-software-turnos | E5: =IF(OR(C5="",C5=0),"",D5/C5) | G5: Pendiente | H5: Excel vs software de turnos: cuándo basta y cuándo no (2026) | I5: Cuándo te basta Excel para el cuadrante y cuándo no. Comparativa honesta, plantilla Excel gratis y software de turnos con IA desde 29 €/mes. | L5: =IF(OR(F5="",K5=""),"",F5-K5) | M5: =IF(OR(C5="",F5=""),"",IF(AND(F5>=4,F5<=15,C5>=20),"Quick win",IF(AND(F5<=5,E5<0.02),"Título roto","Revisar"))) | N5: =IF(H5="","",LEN(H5)) | O5: =IF(I5="","",LEN(I5))
E6: =IF(OR(C6="",C6=0),"",D6/C6) | L6: =IF(OR(F6="",K6=""),"",F6-K6) | M6: =IF(OR(C6="",F6=""),"",IF(AND(F6>=4,F6<=15,C6>=20),"Quick win",IF(AND(F6<=5,E6<0.02),"Título roto","Revisar"))) | N6: =IF(H6="","",LEN(H6)) | O6: =IF(I6="","",LEN(I6))
E7: =IF(OR(C7="",C7=0),"",D7/C7) | L7: =IF(OR(F7="",K7=""),"",F7-K7) | M7: =IF(OR(C7="",F7=""),"",IF(AND(F7>=4,F7<=15,C7>=20),"Quick win",IF(AND(F7<=5,E7<0.02),"Título roto","Revisar"))) | N7: =IF(H7="","",LEN(H7)) | O7: =IF(I7="","",LEN(I7))
E8: =IF(OR(C8="",C8=0),"",D8/C8) | L8: =IF(OR(F8="",K8=""),"",F8-K8) | M8: =IF(OR(C8="",F8=""),"",IF(AND(F8>=4,F8<=15,C8>=20),"Quick win",IF(AND(F8<=5,E8<0.02),"Título roto","Revisar"))) | N8: =IF(H8="","",LEN(H8)) | O8: =IF(I8="","",LEN(I8))
E9: =IF(OR(C9="",C9=0),"",D9/C9) | L9: =IF(OR(F9="",K9=""),"",F9-K9) | M9: =IF(OR(C9="",F9=""),"",IF(AND(F9>=4,F9<=15,C9>=20),"Quick win",IF(AND(F9<=5,E9<0.02),"Título roto","Revisar"))) | N9: =IF(H9="","",LEN(H9)) | O9: =IF(I9="","",LEN(I9))
E10: =IF(OR(C10="",C10=0),"",D10/C10) | L10: =IF(OR(F10="",K10=""),"",F10-K10) | M10: =IF(OR(C10="",F10=""),"",IF(AND(F10>=4,F10<=15,C10>=20),"Quick win",IF(AND(F10<=5,E10<0.02),"Título roto","Revisar"))) | N10: =IF(H10="","",LEN(H10)) | O10: =IF(I10="","",LEN(I10))
E11: =IF(OR(C11="",C11=0),"",D11/C11) | L11: =IF(OR(F11="",K11=""),"",F11-K11) | M11: =IF(OR(C11="",F11=""),"",IF(AND(F11>=4,F11<=15,C11>=20),"Quick win",IF(AND(F11<=5,E11<0.02),"Título roto","Revisar"))) | N11: =IF(H11="","",LEN(H11)) | O11: =IF(I11="","",LEN(I11))
E12: =IF(OR(C12="",C12=0),"",D12/C12) | L12: =IF(OR(F12="",K12=""),"",F12-K12) | M12: =IF(OR(C12="",F12=""),"",IF(AND(F12>=4,F12<=15,C12>=20),"Quick win",IF(AND(F12<=5,E12<0.02),"Título roto","Revisar"))) | N12: =IF(H12="","",LEN(H12)) | O12: =IF(I12="","",LEN(I12))
E13: =IF(OR(C13="",C13=0),"",D13/C13) | L13: =IF(OR(F13="",K13=""),"",F13-K13) | M13: =IF(OR(C13="",F13=""),"",IF(AND(F13>=4,F13<=15,C13>=20),"Quick win",IF(AND(F13<=5,E13<0.02),"Título roto","Revisar"))) | N13: =IF(H13="","",LEN(H13)) | O13: =IF(I13="","",LEN(I13))
E14: =IF(OR(C14="",C14=0),"",D14/C14) | L14: =IF(OR(F14="",K14=""),"",F14-K14) | M14: =IF(OR(C14="",F14=""),"",IF(AND(F14>=4,F14<=15,C14>=20),"Quick win",IF(AND(F14<=5,E14<0.02),"Título roto","Revisar"))) | N14: =IF(H14="","",LEN(H14)) | O14: =IF(I14="","",LEN(I14))
E15: =IF(OR(C15="",C15=0),"",D15/C15) | L15: =IF(OR(F15="",K15=""),"",F15-K15) | M15: =IF(OR(C15="",F15=""),"",IF(AND(F15>=4,F15<=15,C15>=20),"Quick win",IF(AND(F15<=5,E15<0.02),"Título roto","Revisar"))) | N15: =IF(H15="","",LEN(H15)) | O15: =IF(I15="","",LEN(I15))
E16: =IF(OR(C16="",C16=0),"",D16/C16) | L16: =IF(OR(F16="",K16=""),"",F16-K16) | M16: =IF(OR(C16="",F16=""),"",IF(AND(F16>=4,F16<=15,C16>=20),"Quick win",IF(AND(F16<=5,E16<0.02),"Título roto","Revisar"))) | N16: =IF(H16="","",LEN(H16)) | O16: =IF(I16="","",LEN(I16))
E17: =IF(OR(C17="",C17=0),"",D17/C17) | L17: =IF(OR(F17="",K17=""),"",F17-K17) | M17: =IF(OR(C17="",F17=""),"",IF(AND(F17>=4,F17<=15,C17>=20),"Quick win",IF(AND(F17<=5,E17<0.02),"Título roto","Revisar"))) | N17: =IF(H17="","",LEN(H17)) | O17: =IF(I17="","",LEN(I17))
... E45: =IF(OR(C45="",C45=0),"",D45/C45) | L45: =IF(OR(F45="",K45=""),"",F45-K45) | M45: =IF(OR(C45="",F45=""),"",IF(AND(F45>=4,F45<=15,C45>=20),"Quick win",IF(AND(F45<=5,E45<0.02),"Título roto","Revisar"))) | N45: =IF(H45="","",LEN(H45)) | O45: =IF(I45="","",LEN(I45))
